Workbook

Sheet Navigation and Summary
B2: www.ExcelDataPro.com
B3: Student Fee Collection System
B5: Navigation Index and Fee Summary Report
F6: A.Y. | G6: 2025-26
B7: Fee Receipt Sheet | E7: Fee Pending Sheet | F7: Total Fee Due | G7: Fee Received | H7: Outstanding Summary | I7: Difference
B8: Class | C8: Class Fee | D8: Fee Collection Navigation | E8: Pending Fee Navigation | F8: Class-Wise | G8: Class-Wise | H8: Class-Wise
B9: CRECHE | C9: 650 | D9: =HYPERLINK("#"&"'Fee Receipt (Class-wise)'!C2",B9) -> CRECHE | E9: =HYPERLINK("#"&"'Fee Pending (Class-wise)'!C3",B9) -> CRECHE | F9: =C9*49 -> 31850 | G9: =F9-H9 -> 7860 | H9: ='Fee Receipt (Class-wise)'!K65 -> 23990 | I9: =F9-(G9+H9) -> 0
B10: Nur-1 | C10: 650 | D10: =HYPERLINK("#"&"'Fee Receipt (Class-wise)'!C69",B10) -> Nur-1 | E10: =HYPERLINK("#"&"'Fee Pending (Class-wise)'!C40",B10) -> Nur-1 | F10: =C10*54 -> 35100 | G10: =F10-H10 -> 9250 | H10: ='Fee Receipt (Class-wise)'!K132 -> 25850 | I10: =F10-(G10+H10) -> 0
B11: Nur-2 | C11: 650 | D11: =HYPERLINK("#"&"'Fee Receipt (Class-wise)'!C136",B11) -> Nur-2 | E11: =HYPERLINK("#"&"'Fee Pending (Class-wise)'!C77",B11) -> Nur-2 | F11: =C11*60 -> 39000 | G11: =F11-H11 -> 11790 | H11: ='Fee Receipt (Class-wise)'!K199 -> 27210 | I11: =F11-(G11+H11) -> 0
B12: KG-1 | C12: 650 | D12: =HYPERLINK("#"&"'Fee Receipt (Class-wise)'!C203",B12) -> KG-1 | E12: =HYPERLINK("#"&"'Fee Pending (Class-wise)'!C114",B12) -> KG-1 | F12: =C12*60 -> 39000 | G12: =F12-H12 -> 13900 | H12: ='Fee Receipt (Class-wise)'!K266 -> 25100 | I12: =F12-(G12+H12) -> 0
B13: KG-2 | C13: 650 | D13: =HYPERLINK("#"&"'Fee Receipt (Class-wise)'!C270",B13) -> KG-2 | E13: =HYPERLINK("#"&"'Fee Pending (Class-wise)'!C151",B13) -> KG-2 | F13: =C13*60 -> 39000 | G13: =F13-H13 -> 16640 | H13: ='Fee Receipt (Class-wise)'!K333 -> 22360 | I13: =F13-(G13+H13) -> 0
B14: BASIC 1A | C14: 710 | D14: =HYPERLINK("#"&"'Fee Receipt (Class-wise)'!C337",B14) -> BASIC 1A | E14: =HYPERLINK("#"&"'Fee Pending (Class-wise)'!C188",B14) -> BASIC 1A | F14: =C14*60 -> 42600 | G14: =F14-H14 -> 9600 | H14: ='Fee Receipt (Class-wise)'!K400 -> 33000 | I14: =F14-(G14+H14) -> 0
B15: BASIC 1B | C15: 710 | D15: =HYPERLINK("#"&"'Fee Receipt (Class-wise)'!C404",B15) -> BASIC 1B | E15: =HYPERLINK("#"&"'Fee Pending (Class-wise)'!C225",B15) -> BASIC 1B | F15: =C15*60 -> 42600 | G15: =F15-H15 -> 11130 | H15: ='Fee Receipt (Class-wise)'!K467 -> 31470 | I15: =F15-(G15+H15) -> 0
B16: BASIC 2A | C16: 710 | D16: =HYPERLINK("#"&"'Fee Receipt (Class-wise)'!C471",B16) -> BASIC 2A | E16: =HYPERLINK("#"&"'Fee Pending (Class-wise)'!C262",B16) -> BASIC 2A | F16: =C16*60 -> 42600 | G16: =F16-H16 -> 10480 | H16: ='Fee Receipt (Class-wise)'!K534 -> 32120 | I16: =F16-(G16+H16) -> 0
B17: BASIC 2B | C17: 710 | D17: =HYPERLINK("#"&"'Fee Receipt (Class-wise)'!C538",B17) -> BASIC 2B | E17: =HYPERLINK("#"&"'Fee Pending (Class-wise)'!C299",B17) -> BASIC 2B | F17: =C17*60 -> 42600 | G17: =F17-H17 -> 8870 | H17: ='Fee Receipt (Class-wise)'!K601 -> 33730 | I17: =F17-(G17+H17) -> 0
B18: BASIC 3A | C18: 710 | D18: =HYPERLINK("#"&"'Fee Receipt (Class-wise)'!C605",B18) -> BASIC 3A | E18: =HYPERLINK("#"&"'Fee Pending (Class-wise)'!C336",B18) -> BASIC 3A | F18: =C18*60 -> 42600 | G18: =F18-H18 -> 12120 | H18: ='Fee Receipt (Class-wise)'!K668 -> 30480 | I18: =F18-(G18+H18) -> 0
B19: BASIC 3B | C19: 710 | D19: =HYPERLINK("#"&"'Fee Receipt (Class-wise)'!C672",B19) -> BASIC 3B | E19: =HYPERLINK("#"&"'Fee Pending (Class-wise)'!C373",B19) -> BASIC 3B | F19: =C19*60 -> 42600 | G19: =F19-H19 -> 14010 | H19: ='Fee Receipt (Class-wise)'!K735 -> 28590 | I19: =F19-(G19+H19) -> 0
B20: BASIC 4A | C20: 760 | D20: =HYPERLINK("#"&"'Fee Receipt (Class-wise)'!C739",B20) -> BASIC 4A | E20: =HYPERLINK("#"&"'Fee Pending (Class-wise)'!C410",B20) -> BASIC 4A | F20: =C20*60 -> 45600 | G20: =F20-H20 -> 10660 | H20: ='Fee Receipt (Class-wise)'!K802 -> 34940 | I20: =F20-(G20+H20) -> 0
B21: BASIC 4B | C21: 760 | D21: =HYPERLINK("#"&"'Fee Receipt (Class-wise)'!C806",B21) -> BASIC 4B | E21: =HYPERLINK("#"&"'Fee Pending (Class-wise)'!C447",B21) -> BASIC 4B | F21: =C21*60 -> 45600 | G21: =F21-H21 -> 14010 | H21: ='Fee Receipt (Class-wise)'!K869 -> 31590 | I21: =F21-(G21+H21) -> 0
B22: BASIC 5A | C22: 760 | D22: =HYPERLINK("#"&"'Fee Receipt (Class-wise)'!C873",B22) -> BASIC 5A | E22: =HYPERLINK("#"&"'Fee Pending (Class-wise)'!C484",B22) -> BASIC 5A | F22: =C22*60 -> 45600 | G22: =F22-H22 -> 15750 | H22: ='Fee Receipt (Class-wise)'!K936 -> 29850 | I22: =F22-(G22+H22) -> 0
B23: BASIC 5B | C23: 760 | D23: =HYPERLINK("#"&"'Fee Receipt (Class-wise)'!C940",B23) -> BASIC 5B | E23: =HYPERLINK("#"&"'Fee Pending (Class-wise)'!C521",B23) -> BASIC 5B | F23: =C23*60 -> 45600 | G23: =F23-H23 -> 17390 | H23: ='Fee Receipt (Class-wise)'!K1003 -> 28210 | I23: =F23-(G23+H23) -> 0
B24: BASIC 6A | C24: 760 | D24: =HYPERLINK("#"&"'Fee Receipt (Class-wise)'!C1007",B24) -> BASIC 6A | E24: =HYPERLINK("#"&"'Fee Pending (Class-wise)'!C558",B24) -> BASIC 6A | F24: =C24*60 -> 45600 | G24: =F24-H24 -> 18320 | H24: ='Fee Receipt (Class-wise)'!K1070 -> 27280 | I24: =F24-(G24+H24) -> 0
B25: BASIC 6B | C25: 760 | D25: =HYPERLINK("#"&"'Fee Receipt (Class-wise)'!C1074",B25) -> BASIC 6B | E25: =HYPERLINK("#"&"'Fee Pending (Class-wise)'!C595",B25) -> BASIC 6B | F25: =C25*60 -> 45600 | G25: =F25-H25 -> 14620 | H25: ='Fee Receipt (Class-wise)'!K1137 -> 30980 | I25: =F25-(G25+H25) -> 0
B26: BASIC 7A | C26: 980 | D26: =HYPERLINK("#"&"'Fee Receipt (Class-wise)'!C1141",B26) -> BASIC 7A | E26: =HYPERLINK("#"&"'Fee Pending (Class-wise)'!C632",B26) -> BASIC 7A | F26: =C26*60 -> 58800 | G26: =F26-H26 -> 15690 | H26: ='Fee Receipt (Class-wise)'!K1204 -> 43110 | I26: =F26-(G26+H26) -> 0
B27: BASIC 7B | C27: 980 | D27: =HYPERLINK("#"&"'Fee Receipt (Class-wise)'!C1208",B27) -> BASIC 7B | E27: =HYPERLINK("#"&"'Fee Pending (Class-wise)'!C669",B27) -> BASIC 7B | F27: =C27*60 -> 58800 | G27: =F27-H27 -> 17970 | H27: ='Fee Receipt (Class-wise)'!K1271 -> 40830 | I27: =F27-(G27+H27) -> 0
B28: BASIC 8A | C28: 980 | D28: =HYPERLINK("#"&"'Fee Receipt (Class-wise)'!C1275",B28) -> BASIC 8A | E28: =HYPERLINK("#"&"'Fee Pending (Class-wise)'!C706",B28) -> BASIC 8A | F28: =C28*60 -> 58800 | G28: =F28-H28 -> 16250 | H28: ='Fee Receipt (Class-wise)'!K1338 -> 42550 | I28: =F28-(G28+H28) -> 0
B29: BASIC 8B | C29: 980 | D29: =HYPERLINK("#"&"'Fee Receipt (Class-wise)'!C1342",B29) -> BASIC 8B | E29: =HYPERLINK("#"&"'Fee Pending (Class-wise)'!C743",B29) -> BASIC 8B | F29: =C29*60 -> 58800 | G29: =F29-H29 -> 17150 | H29: ='Fee Receipt (Class-wise)'!K1405 -> 41650 | I29: =F29-(G29+H29) -> 0
B30: BASIC 9A | C30: 4160 | D30: =HYPERLINK("#"&"'Fee Receipt (Class-wise)'!C1409",B30) -> BASIC 9A | E30: =HYPERLINK("#"&"'Fee Pending (Class-wise)'!C780",B30) -> BASIC 9A | F30: =C30*60 -> 249600 | G30: =F30-H30 -> -4160 | H30: ='Fee Receipt (Class-wise)'!K1473 -> 253760 | I30: =F30-(G30+H30) -> 0
B31: BASIC 9B | C31: 4160 | D31: =HYPERLINK("#"&"'Fee Receipt (Class-wise)'!C1409",B31) -> BASIC 9B | E31: =HYPERLINK("#"&"'Fee Pending (Class-wise)'!C780",B31) -> BASIC 9B | F31: =C31*60 -> 249600 | G31: =F31-H31 -> 0 | H31: ='Fee Receipt (Class-wise)'!K1540 -> 249600 | I31: =F31-(G31+H31) -> 0
B39: Total | F39: =SUM(F9:F38) -> 1447550 | G39: =SUM(G9:G38) -> 279300 | H39: =SUM(H9:H38) -> 1168250 | I39: =F39-(G39+H39) -> 0

Sheet Fee Receipt (Class-wise)
A1: Fee Receipt (Class-wise)
A2: 1 | B2: Class | C2: =IF('Navigation and Summary'!$B$9="", "", 'Navigation and Summary'!$B$9) -> CRECHE | E2: Class Fee | F2: =IF('Navigation and Summary'!$C$9="", "", 'Navigation and Summary'!$C$9) -> 650 | G2: A.Y. | H2: =IF(C2="", "", 'Navigation and Summary'!$G$6) -> 2025-26
B3: 1) Fee Received Details
B4: Roll No. | C4: Name | D4: SEX | E4: Payment-1 | F4: Payment-2 | G4: Payment-3 | H4: Payment-4 | I4: Payment-5 | J4: Total Payment | K4: Pending Fee
B5: 1 | C5: ABDUL KARIM TIJANI | D5: M | E5: 150 | J5: =IF(SUM(E5:I5)=0, "", SUM(E5:I5)) -> 150 | K5: =IFERROR(IF(($F$2-J5)=0, 0, ($F$2-J5)),$F$2) -> 500
B6: 2 | C6: ABDULAI MUSHARAFATU | D6: F | E6: 650 | J6: =IF(SUM(E6:I6)=0, "", SUM(E6:I6)) -> 650 | K6: =IFERROR(IF(($F$2-J6)=0, 0, ($F$2-J6)),$F$2) -> 0
B7: 3 | C7: ADEPA JAYDA | D7: F | E7: 200 | J7: =IF(SUM(E7:I7)=0, "", SUM(E7:I7)) -> 200 | K7: =IFERROR(IF(($F$2-J7)=0, 0, ($F$2-J7)),$F$2) -> 450
B8: 4 | C8: AFARI JAMES SHININGONE | D8: M | E8: 310 | J8: =IF(SUM(E8:I8)=0, "", SUM(E8:I8)) -> 310 | K8: =IFERROR(IF(($F$2-J8)=0, 0, ($F$2-J8)),$F$2) -> 340
B9: 5 | C9: AGBOVI ELIZAH | D9: M | E9: 650 | J9: =IF(SUM(E9:I9)=0, "", SUM(E9:I9)) -> 650 | K9: =IFERROR(IF(($F$2-J9)=0, 0, ($F$2-J9)),$F$2) -> 0
B10: 6 | C10: AHORLU JAYDEN BILLINGS | D10: M | E10: 650 | J10: =IF(SUM(E10:I10)=0, "", SUM(E10:I10)) -> 650 | K10: =IFERROR(IF(($F$2-J10)=0, 0, ($F$2-J10)),$F$2) -> 0
B11: 7 | C11: ALORWUYIE FOLI X GIDEON | D11: M | E11: 650 | J11: =IF(SUM(E11:I11)=0, "", SUM(E11:I11)) -> 650 | K11: =IFERROR(IF(($F$2-J11)=0, 0, ($F$2-J11)),$F$2) -> 0
B12: 8 | C12: AMISSAH NKUNIM ELEANOR | D12: F | E12: 650 | J12: =IF(SUM(E12:I12)=0, "", SUM(E12:I12)) -> 650 | K12: =IFERROR(IF(($F$2-J12)=0, 0, ($F$2-J12)),$F$2) -> 0
B13: 9 | C13: ARTHUR ABOAGYE BILLINGS | D13: M | J13: =IF(SUM(E13:I13)=0, "", SUM(E13:I13)) | K13: =IFERROR(IF(($F$2-J13)=0, 0, ($F$2-J13)),$F$2) -> 650
B14: 10 | C14: AVISON SELORM | D14: M | E14: 650 | J14: =IF(SUM(E14:I14)=0, "", SUM(E14:I14)) -> 650 | K14: =IFERROR(IF(($F$2-J14)=0, 0, ($F$2-J14)),$F$2) -> 0
B15: 11 | C15: BOADI SOLOMON | D15: M | E15: 450 | J15: =IF(SUM(E15:I15)=0, "", SUM(E15:I15)) -> 450 | K15: =IFERROR(IF(($F$2-J15)=0, 0, ($F$2-J15)),$F$2) -> 200
B16: 12 | C16: DANQUAH BENYI DAVINA | D16: F | J16: =IF(SUM(E16:I16)=0, "", SUM(E16:I16)) | K16: =IFERROR(IF(($F$2-J16)=0, 0, ($F$2-J16)),$F$2) -> 650
B17: 13 | C17: DZOKOTO BERNICE | D17: F | J17: =IF(SUM(E17:I17)=0, "", SUM(E17:I17)) | K17: =IFERROR(IF(($F$2-J17)=0, 0, ($F$2-J17)),$F$2) -> 650
B18: 14 | C18: FIAGBENYA KLENAM MAYNARD | D18: M | E18: 200 | F18: 200 | G18: 250 | J18: =IF(SUM(E18:I18)=0, "", SUM(E18:I18)) -> 650 | K18: =IFERROR(IF(($F$2-J18)=0, 0, ($F$2-J18)),$F$2) -> 0
B19: 15 | C19: GYAMFI BERVELYN | D19: F | J19: =IF(SUM(E19:I19)=0, "", SUM(E19:I19)) | K19: =IFERROR(IF(($F$2-J19)=0, 0, ($F$2-J19)),$F$2) -> 650
B20: 16 | C20: KOSIPAH JOYCELYN | D20: F | J20: =IF(SUM(E20:I20)=0, "", SUM(E20:I20)) | K20: =IFERROR(IF(($F$2-J20)=0, 0, ($F$2-J20)),$F$2) -> 650
B21: 17 | C21: KPELI SENAM | D21: F | J21: =IF(SUM(E21:I21)=0, "", SUM(E21:I21)) | K21: =IFERROR(IF(($F$2-J21)=0, 0, ($F$2-J21)),$F$2) -> 650
B22: 18 | C22: KPELI SEYRAM | D22: F | J22: =IF(SUM(E22:I22)=0, "", SUM(E22:I22)) | K22: =IFERROR(IF(($F$2-J22)=0, 0, ($F$2-J22)),$F$2) -> 650
B23: 19 | C23: ABABIO SEYRAM ELOISE | D23: F | E23: 300 | F23: 200 | J23: =IF(SUM(E23:I23)=0, "", SUM(E23:I23)) -> 500 | K23: =IFERROR(IF(($F$2-J23)=0, 0, ($F$2-J23)),$F$2) -> 150
B24: 20 | C24: KORMEGBE JEFFERY | D24: M | E24: 450 | F24: 200 | J24: =IF(SUM(E24:I24)=0, "", SUM(E24:I24)) -> 650 | K24: =IFERROR(IF(($F$2-J24)=0, 0, ($F$2-J24)),$F$2) -> 0
B25: 21 | C25: OSMAN KADIJAH | D25: F | J25: =IF(SUM(E25:I25)=0, "", SUM(E25:I25)) | K25: =IFERROR(IF(($F$2-J25)=0, 0, ($F$2-J25)),$F$2) -> 650
B26: 22 | C26: QUANSAH DIGNITY | D26: F | E26: 200 | F26: 200 | J26: =IF(SUM(E26:I26)=0, "", SUM(E26:I26)) -> 400 | K26: =IFERROR(IF(($F$2-J26)=0, 0, ($F$2-J26)),$F$2) -> 250
B27: 23 | C27: SADIQ SHAREEF | D27: M | J27: =IF(SUM(E27:I27)=0, "", SUM(E27:I27)) | K27: =IFERROR(IF(($F$2-J27)=0, 0, ($F$2-J27)),$F$2) -> 650
B28: 24 | C28: WIREKO ELIANNA | D28: F | E28: 650 | J28: =IF(SUM(E28:I28)=0, "", SUM(E28:I28)) -> 650 | K28: =IFERROR(IF(($F$2-J28)=0, 0, ($F$2-J28)),$F$2) -> 0
B29: 25 | J29: =IF(SUM(E29:I29)=0, "", SUM(E29:I29)) | K29: =IFERROR(IF(($F$2-J29)=0, 0, ($F$2-J29)),$F$2) -> 650
B30: 26 | J30: =IF(SUM(E30:I30)=0, "", SUM(E30:I30)) | K30: =IFERROR(IF(($F$2-J30)=0, 0, ($F$2-J30)),$F$2) -> 650
B31: 27 | J31: =IF(SUM(E31:I31)=0, "", SUM(E31:I31)) | K31: =IFERROR(IF(($F$2-J31)=0, 0, ($F$2-J31)),$F$2) -> 650
B32: 28 | J32: =IF(SUM(E32:I32)=0, "", SUM(E32:I32)) | K32: =IFERROR(IF(($F$2-J32)=0, 0, ($F$2-J32)),$F$2) -> 650
B33: 29 | J33: =IF(SUM(E33:I33)=0, "", SUM(E33:I33)) | K33: =IFERROR(IF(($F$2-J33)=0, 0, ($F$2-J33)),$F$2) -> 650
B34: 30 | J34: =IF(SUM(E34:I34)=0, "", SUM(E34:I34)) | K34: =IFERROR(IF(($F$2-J34)=0, 0, ($F$2-J34)),$F$2) -> 650
B35: 31 | J35: =IF(SUM(E35:I35)=0, "", SUM(E35:I35)) | K35: =IFERROR(IF(($F$2-J35)=0, 0, ($F$2-J35)),$F$2) -> 650
B36: 32 | J36: =IF(SUM(E36:I36)=0, "", SUM(E36:I36)) | K36: =IFERROR(IF(($F$2-J36)=0, 0, ($F$2-J36)),$F$2) -> 650
B37: 33 | J37: =IF(SUM(E37:I37)=0, "", SUM(E37:I37)) | K37: =IFERROR(IF(($F$2-J37)=0, 0, ($F$2-J37)),$F$2) -> 650
B38: 34 | J38: =IF(SUM(E38:I38)=0, "", SUM(E38:I38)) | K38: =IFERROR(IF(($F$2-J38)=0, 0, ($F$2-J38)),$F$2) -> 650
B39: 35 | J39: =IF(SUM(E39:I39)=0, "", SUM(E39:I39)) | K39: =IFERROR(IF(($F$2-J39)=0, 0, ($F$2-J39)),$F$2) -> 650
B40: 36 | J40: =IF(SUM(E40:I40)=0, "", SUM(E40:I40)) | K40: =IFERROR(IF(($F$2-J40)=0, 0, ($F$2-J40)),$F$2) -> 650
...

Sheet Fee Pending (Class-wise)
A1: Fee Pending (Class-wise)
A2: 1 | B2: Pending Fee Details | H2: Total O/s.
B3: Class-Div | C3: =IF('Fee Receipt (Class-wise)'!C2="", "", 'Fee Receipt (Class-wise)'!C2) -> CRECHE | H3: =IF(C3="", "", H36) -> 23990
B4: A.Y. | C4: =IF(C3="", "", 'Fee Receipt (Class-wise)'!$H$2) -> 2025-26
B5: Roll No. | C5: Name | D5: Pending Fee | F5: Roll No. | G5: Name | H5: Pending Fee
B6: 1 | C6: =IF('Fee Receipt (Class-wise)'!C5="", "", 'Fee Receipt (Class-wise)'!C5) -> ABDUL KARIM TIJANI | D6: ='Fee Receipt (Class-wise)'!K5 -> 500 | F6: 31 | G6: =IF('Fee Receipt (Class-wise)'!C35="", "", 'Fee Receipt (Class-wise)'!C35) | H6: ='Fee Receipt (Class-wise)'!K35 -> 650
B7: 2 | C7: =IF('Fee Receipt (Class-wise)'!C6="", "", 'Fee Receipt (Class-wise)'!C6) -> ABDULAI MUSHARAFATU | D7: ='Fee Receipt (Class-wise)'!K6 -> 0 | F7: 32 | G7: =IF('Fee Receipt (Class-wise)'!C36="", "", 'Fee Receipt (Class-wise)'!C36) | H7: ='Fee Receipt (Class-wise)'!K36 -> 650
B8: 3 | C8: =IF('Fee Receipt (Class-wise)'!C7="", "", 'Fee Receipt (Class-wise)'!C7) -> ADEPA JAYDA | D8: ='Fee Receipt (Class-wise)'!K7 -> 450 | F8: 33 | G8: =IF('Fee Receipt (Class-wise)'!C37="", "", 'Fee Receipt (Class-wise)'!C37) | H8: ='Fee Receipt (Class-wise)'!K37 -> 650
B9: 4 | C9: =IF('Fee Receipt (Class-wise)'!C8="", "", 'Fee Receipt (Class-wise)'!C8) -> AFARI JAMES SHININGONE | D9: ='Fee Receipt (Class-wise)'!K8 -> 340 | F9: 34 | G9: =IF('Fee Receipt (Class-wise)'!C38="", "", 'Fee Receipt (Class-wise)'!C38) | H9: ='Fee Receipt (Class-wise)'!K38 -> 650
B10: 5 | C10: =IF('Fee Receipt (Class-wise)'!C9="", "", 'Fee Receipt (Class-wise)'!C9) -> AGBOVI ELIZAH | D10: ='Fee Receipt (Class-wise)'!K9 -> 0 | F10: 35 | G10: =IF('Fee Receipt (Class-wise)'!C39="", "", 'Fee Receipt (Class-wise)'!C39) | H10: ='Fee Receipt (Class-wise)'!K39 -> 650
B11: 6 | C11: =IF('Fee Receipt (Class-wise)'!C10="", "", 'Fee Receipt (Class-wise)'!C10) -> AHORLU JAYDEN BILLINGS | D11: ='Fee Receipt (Class-wise)'!K10 -> 0 | F11: 36 | G11: =IF('Fee Receipt (Class-wise)'!C40="", "", 'Fee Receipt (Class-wise)'!C40) | H11: ='Fee Receipt (Class-wise)'!K40 -> 650
B12: 7 | C12: =IF('Fee Receipt (Class-wise)'!C11="", "", 'Fee Receipt (Class-wise)'!C11) -> ALORWUYIE FOLI X GIDEON | D12: ='Fee Receipt (Class-wise)'!K11 -> 0 | F12: 37 | G12: =IF('Fee Receipt (Class-wise)'!C41="", "", 'Fee Receipt (Class-wise)'!C41) | H12: ='Fee Receipt (Class-wise)'!K41 -> 650
B13: 8 | C13: =IF('Fee Receipt (Class-wise)'!C12="", "", 'Fee Receipt (Class-wise)'!C12) -> AMISSAH NKUNIM ELEANOR | D13: ='Fee Receipt (Class-wise)'!K12 -> 0 | F13: 38 | G13: =IF('Fee Receipt (Class-wise)'!C42="", "", 'Fee Receipt (Class-wise)'!C42) | H13: ='Fee Receipt (Class-wise)'!K42 -> 650
B14: 9 | C14: =IF('Fee Receipt (Class-wise)'!C13="", "", 'Fee Receipt (Class-wise)'!C13) -> ARTHUR ABOAGYE BILLINGS | D14: ='Fee Receipt (Class-wise)'!K13 -> 650 | F14: 39 | G14: =IF('Fee Receipt (Class-wise)'!C43="", "", 'Fee Receipt (Class-wise)'!C43) | H14: ='Fee Receipt (Class-wise)'!K43 -> 650
B15: 10 | C15: =IF('Fee Receipt (Class-wise)'!C14="", "", 'Fee Receipt (Class-wise)'!C14) -> AVISON SELORM | D15: ='Fee Receipt (Class-wise)'!K14 -> 0 | F15: 40 | G15: =IF('Fee Receipt (Class-wise)'!C44="", "", 'Fee Receipt (Class-wise)'!C44) | H15: ='Fee Receipt (Class-wise)'!K44 -> 650
B16: 11 | C16: =IF('Fee Receipt (Class-wise)'!C15="", "", 'Fee Receipt (Class-wise)'!C15) -> BOADI SOLOMON | D16: ='Fee Receipt (Class-wise)'!K15 -> 200 | F16: 41 | G16: =IF('Fee Receipt (Class-wise)'!C45="", "", 'Fee Receipt (Class-wise)'!C45) | H16: ='Fee Receipt (Class-wise)'!K45 -> 650
B17: 12 | C17: =IF('Fee Receipt (Class-wise)'!C16="", "", 'Fee Receipt (Class-wise)'!C16) -> DANQUAH BENYI DAVINA | D17: ='Fee Receipt (Class-wise)'!K16 -> 650 | F17: 42 | G17: =IF('Fee Receipt (Class-wise)'!C46="", "", 'Fee Receipt (Class-wise)'!C46) | H17: ='Fee Receipt (Class-wise)'!K46 -> 650
B18: 13 | C18: =IF('Fee Receipt (Class-wise)'!C17="", "", 'Fee Receipt (Class-wise)'!C17) -> DZOKOTO BERNICE | D18: ='Fee Receipt (Class-wise)'!K17 -> 650 | F18: 43 | G18: =IF('Fee Receipt (Class-wise)'!C47="", "", 'Fee Receipt (Class-wise)'!C47) | H18: ='Fee Receipt (Class-wise)'!K47 -> 650
B19: 14 | C19: =IF('Fee Receipt (Class-wise)'!C100="", "", 'Fee Receipt (Class-wise)'!C100) -> TSIKATA MAKAFUI JEFFERY | D19: ='Fee Receipt (Class-wise)'!K18 -> 0 | F19: 44 | G19: =IF('Fee Receipt (Class-wise)'!C48="", "", 'Fee Receipt (Class-wise)'!C48) | H19: ='Fee Receipt (Class-wise)'!K48 -> 650
B20: 15 | C20: =IF('Fee Receipt (Class-wise)'!C19="", "", 'Fee Receipt (Class-wise)'!C19) -> GYAMFI BERVELYN | D20: ='Fee Receipt (Class-wise)'!K19 -> 650 | F20: 45 | G20: =IF('Fee Receipt (Class-wise)'!C49="", "", 'Fee Receipt (Class-wise)'!C49) | H20: ='Fee Receipt (Class-wise)'!K49 -> 650
B21: 16 | C21: =IF('Fee Receipt (Class-wise)'!C20="", "", 'Fee Receipt (Class-wise)'!C20) -> KOSIPAH JOYCELYN | D21: ='Fee Receipt (Class-wise)'!K20 -> 650 | F21: 46 | G21: =IF('Fee Receipt (Class-wise)'!C50="", "", 'Fee Receipt (Class-wise)'!C50) | H21: ='Fee Receipt (Class-wise)'!K50 -> 650
B22: 17 | C22: =IF('Fee Receipt (Class-wise)'!C21="", "", 'Fee Receipt (Class-wise)'!C21) -> KPELI SENAM | D22: ='Fee Receipt (Class-wise)'!K21 -> 650 | F22: 47 | G22: =IF('Fee Receipt (Class-wise)'!C51="", "", 'Fee Receipt (Class-wise)'!C51) | H22: ='Fee Receipt (Class-wise)'!K51 -> 650
B23: 18 | C23: =IF('Fee Receipt (Class-wise)'!C22="", "", 'Fee Receipt (Class-wise)'!C22) -> KPELI SEYRAM | D23: ='Fee Receipt (Class-wise)'!K22 -> 650 | F23: 48 | G23: =IF('Fee Receipt (Class-wise)'!C52="", "", 'Fee Receipt (Class-wise)'!C52) | H23: ='Fee Receipt (Class-wise)'!K52 -> 650
B24: 19 | C24: =IF('Fee Receipt (Class-wise)'!C23="", "", 'Fee Receipt (Class-wise)'!C23) -> ABABIO SEYRAM ELOISE | D24: ='Fee Receipt (Class-wise)'!K23 -> 150 | F24: 49 | G24: =IF('Fee Receipt (Class-wise)'!C53="", "", 'Fee Receipt (Class-wise)'!C53) | H24: ='Fee Receipt (Class-wise)'!K53 -> 650
B25: 20 | C25: =IF('Fee Receipt (Class-wise)'!C24="", "", 'Fee Receipt (Class-wise)'!C24) -> KORMEGBE JEFFERY | D25: ='Fee Receipt (Class-wise)'!K24 -> 0 | F25: 50 | G25: =IF('Fee Receipt (Class-wise)'!C54="", "", 'Fee Receipt (Class-wise)'!C54) | H25: ='Fee Receipt (Class-wise)'!K54 -> 650
B26: 21 | C26: =IF('Fee Receipt (Class-wise)'!C25="", "", 'Fee Receipt (Class-wise)'!C25) -> OSMAN KADIJAH | D26: ='Fee Receipt (Class-wise)'!K25 -> 650 | F26: 51 | G26: =IF('Fee Receipt (Class-wise)'!C55="", "", 'Fee Receipt (Class-wise)'!C55) | H26: ='Fee Receipt (Class-wise)'!K55 -> 650
B27: 22 | C27: =IF('Fee Receipt (Class-wise)'!C26="", "", 'Fee Receipt (Class-wise)'!C26) -> QUANSAH DIGNITY | D27: ='Fee Receipt (Class-wise)'!K26 -> 250 | F27: 52 | G27: =IF('Fee Receipt (Class-wise)'!C56="", "", 'Fee Receipt (Class-wise)'!C56) | H27: ='Fee Receipt (Class-wise)'!K56 -> 650
B28: 23 | C28: =IF('Fee Receipt (Class-wise)'!C27="", "", 'Fee Receipt (Class-wise)'!C27) -> SADIQ SHAREEF | D28: ='Fee Receipt (Class-wise)'!K27 -> 650 | F28: 53 | G28: =IF('Fee Receipt (Class-wise)'!C57="", "", 'Fee Receipt (Class-wise)'!C57) | H28: ='Fee Receipt (Class-wise)'!K57 -> 650
B29: 24 | C29: =IF('Fee Receipt (Class-wise)'!C28="", "", 'Fee Receipt (Class-wise)'!C28) -> WIREKO ELIANNA | D29: ='Fee Receipt (Class-wise)'!K28 -> 0 | F29: 54 | G29: =IF('Fee Receipt (Class-wise)'!C58="", "", 'Fee Receipt (Class-wise)'!C58) | H29: ='Fee Receipt (Class-wise)'!K58 -> 650
B30: 25 | C30: =IF('Fee Receipt (Class-wise)'!C29="", "", 'Fee Receipt (Class-wise)'!C29) | D30: ='Fee Receipt (Class-wise)'!K29 -> 650 | F30: 55 | G30: =IF('Fee Receipt (Class-wise)'!C59="", "", 'Fee Receipt (Class-wise)'!C59) | H30: ='Fee Receipt (Class-wise)'!K59 -> 650
B31: 26 | C31: =IF('Fee Receipt (Class-wise)'!C30="", "", 'Fee Receipt (Class-wise)'!C30) | D31: ='Fee Receipt (Class-wise)'!K30 -> 650 | F31: 56 | G31: =IF('Fee Receipt (Class-wise)'!C60="", "", 'Fee Receipt (Class-wise)'!C60) | H31: ='Fee Receipt (Class-wise)'!K60 -> 650
... B35: 30 | C35: =IF('Fee Receipt (Class-wise)'!C34="", "", 'Fee Receipt (Class-wise)'!C34) | D35: ='Fee Receipt (Class-wise)'!K34 -> 650 | F35: 60 | G35: =IF('Fee Receipt (Class-wise)'!C64="", "", 'Fee Receipt (Class-wise)'!C64) | H35: ='Fee Receipt (Class-wise)'!K64 -> 650
F36: Total Outstanding | H36: =SUM(D6:D35)+SUM(H6:H24) -> 23990
A39: 2 | B39: Pending Fee Details | H39: Total O/s.
B40: Class-Div | C40: =IF('Fee Receipt (Class-wise)'!C69="", "", 'Fee Receipt (Class-wise)'!C69) -> Nur-1 | H40: =IF(C40="", "", H73) -> 8950
B41: A.Y. | C41: =IF(C40="", "", 'Fee Receipt (Class-wise)'!$H$2) -> 2025-26
B42: Roll No. | C42: Name | D42: Pending Fee | F42: Roll No. | G42: Name | H42: Pending Fee
B43: 1 | C43: ='Fee Receipt (Class-wise)'!C72 -> ABDUL AZIZ MARIAM | D43: ='Fee Receipt (Class-wise)'!K72 -> 350 | F43: 31 | G43: ='Fee Receipt (Class-wise)'!C102 -> 0 | H43: ='Fee Receipt (Class-wise)'!K102 -> 650
B44: 2 | C44: ='Fee Receipt (Class-wise)'!C73 -> ADDY CHRITOPHER | D44: ='Fee Receipt (Class-wise)'!K73 -> 650 | F44: 32 | G44: ='Fee Receipt (Class-wise)'!C103 -> 0 | H44: ='Fee Receipt (Class-wise)'!K103 -> 650
B45: 3 | C45: ='Fee Receipt (Class-wise)'!C74 -> AFLAKPUI LIVINGST0NE | D45: ='Fee Receipt (Class-wise)'!K74 -> 0 | F45: 33 | G45: ='Fee Receipt (Class-wise)'!C104 -> 0 | H45: ='Fee Receipt (Class-wise)'!K104 -> 650
...

Sheet Printing Slot
A1: Paste whole class details in the below light blue zone from previous sheet for which reminder needs to be send.
G3: Enter below details. It will directly reflect in reminder letter.
A5: Sr. No. | B5: Class | C5: Roll No. | D5: Name | E5: Fee Pending | G5: Particulars | J5: Details
A6: 1 | B6: Nur-A | C6: 6 | D6: Farid | E6: 9300 | G6: Fee Reminder Date | J6: 43698
A7: 2 | B7: Nur-A | C7: 16 | D7: Riya | E7: 9300 | G7: Days to pay | J7: 5
A8: 3 | B8: Nur-A | C8: 28 | D8: Girish | E8: 9300 | G8: Latest by | J8: =IFERROR(IF(J6="","", J6+J7), "") -> 43703
A9: 4 | B9: Nur-A | C9: 42 | D9: Zainab | E9: 9300
A10: 5 | B10: Nur-A | C10: 59 | D10: Elango | E10: 9300
A11: 6 | B11: Nur-A | C11: 5 | D11: Elango | E11: 8300
A12: 7 | B12: Nur-A | C12: 15 | D12: Priya | E12: 8300
A13: 8 | B13: Nur-A | C13: 27 | D13: Farid | E13: 8300
A14: 9 | B14: Nur-A | C14: 41 | D14: Vimla | E14: 8300
A15: 10 | B15: Nur-A | C15: 58 | D15: Dipak | E15: 8300
A16: 11 | B16: Nur-A | C16: 4 | D16: Dipak | E16: 6300
A17: 12 | B17: Nur-A | C17: 14 | D17: Neha | E17: 6300
A18: 13 | B18: Nur-A | C18: 26 | D18: Elango | E18: 6300
A19: 14 | B19: Nur-A | C19: 40 | D19: Urmila | E19: 6300
A20: 15 | B20: Nur-A | C20: 57 | D20: Chandrakant | E20: 6300
... A65: 60 | B65: Nur-A | C65: 60 | D65: Farid | E65: 0
A66: Total O/s | E66: 152000
